[2025-04-03T14:09:38.581+0000] {local_task_job_runner.py:123} INFO - ::group::Pre task execution logs
[2025-04-03T14:09:38.605+0000] {taskinstance.py:2614} INFO - Dependencies all met for dep_context=non-requeueable deps ti=<TaskInstance: news_api_collection.store_in_data_lake manual__2025-04-03T13:59:54.182119+00:00 [queued]>
[2025-04-03T14:09:38.617+0000] {taskinstance.py:2614} INFO - Dependencies all met for dep_context=requeueable deps ti=<TaskInstance: news_api_collection.store_in_data_lake manual__2025-04-03T13:59:54.182119+00:00 [queued]>
[2025-04-03T14:09:38.617+0000] {taskinstance.py:2867} INFO - Starting attempt 1 of 2
[2025-04-03T14:09:38.640+0000] {taskinstance.py:2890} INFO - Executing <Task(PythonOperator): store_in_data_lake> on 2025-04-03 13:59:54.182119+00:00
[2025-04-03T14:09:38.663+0000] {standard_task_runner.py:72} INFO - Started process 117762 to run task
[2025-04-03T14:09:38.669+0000] {standard_task_runner.py:104} INFO - Running: ['airflow', 'tasks', 'run', 'news_api_collection', 'store_in_data_lake', 'manual__2025-04-03T13:59:54.182119+00:00', '--job-id', '12', '--raw', '--subdir', 'DAGS_FOLDER/news_scrapper.py', '--cfg-path', '/tmp/tmpg2h2et26']
[2025-04-03T14:09:38.672+0000] {standard_task_runner.py:105} INFO - Job 12: Subtask store_in_data_lake
[2025-04-03T14:09:38.726+0000] {task_command.py:467} INFO - Running <TaskInstance: news_api_collection.store_in_data_lake manual__2025-04-03T13:59:54.182119+00:00 [running]> on host hamza-HP-ProBook-450-G8-Notebook-PC
[2025-04-03T14:09:38.818+0000] {taskinstance.py:3134} INFO - Exporting env vars: AIRFLOW_CTX_DAG_OWNER='retail_mlops' AIRFLOW_CTX_DAG_ID='news_api_collection' AIRFLOW_CTX_TASK_ID='store_in_data_lake' AIRFLOW_CTX_EXECUTION_DATE='2025-04-03T13:59:54.182119+00:00' AIRFLOW_CTX_TRY_NUMBER='1' AIRFLOW_CTX_DAG_RUN_ID='manual__2025-04-03T13:59:54.182119+00:00'
[2025-04-03T14:09:38.820+0000] {logging_mixin.py:190} INFO - Task instance is in running state
[2025-04-03T14:09:38.821+0000] {logging_mixin.py:190} INFO -  Previous state of the Task instance: queued
[2025-04-03T14:09:38.822+0000] {logging_mixin.py:190} INFO - Current task name:store_in_data_lake state:running start_date:2025-04-03 14:09:38.605697+00:00
[2025-04-03T14:09:38.822+0000] {logging_mixin.py:190} INFO - Dag name:news_api_collection and current dag run status:running
[2025-04-03T14:09:38.822+0000] {taskinstance.py:732} INFO - ::endgroup::
[2025-04-03T14:09:38.846+0000] {logging_mixin.py:190} INFO - Articles received in store_in_data_lake: 74
[2025-04-03T14:09:38.868+0000] {taskinstance.py:3313} ERROR - Task failed with exception
Traceback (most recent call last):
  File "/home/hamza/Documents/project/Mlops/myenv/lib/python3.12/site-packages/airflow/models/taskinstance.py", line 768, in _execute_task
    result = _execute_callable(context=context, **execute_callable_kwargs)
             ^^^^^^^^^^^^^^^^^^^^^^^^^^^^^^^^^^^^^^^^^^^^^^^^^^^^^^^^^^^^^
  File "/home/hamza/Documents/project/Mlops/myenv/lib/python3.12/site-packages/airflow/models/taskinstance.py", line 734, in _execute_callable
    return ExecutionCallableRunner(
           ^^^^^^^^^^^^^^^^^^^^^^^^
  File "/home/hamza/Documents/project/Mlops/myenv/lib/python3.12/site-packages/airflow/utils/operator_helpers.py", line 252, in run
    return self.func(*args, **kwargs)
           ^^^^^^^^^^^^^^^^^^^^^^^^^^
  File "/home/hamza/Documents/project/Mlops/myenv/lib/python3.12/site-packages/airflow/models/baseoperator.py", line 424, in wrapper
    return func(self, *args, **kwargs)
           ^^^^^^^^^^^^^^^^^^^^^^^^^^^
  File "/home/hamza/Documents/project/Mlops/myenv/lib/python3.12/site-packages/airflow/operators/python.py", line 238, in execute
    return_value = self.execute_callable()
                   ^^^^^^^^^^^^^^^^^^^^^^^
  File "/home/hamza/Documents/project/Mlops/myenv/lib/python3.12/site-packages/airflow/operators/python.py", line 256, in execute_callable
    return runner.run(*self.op_args, **self.op_kwargs)
           ^^^^^^^^^^^^^^^^^^^^^^^^^^^^^^^^^^^^^^^^^^^
  File "/home/hamza/Documents/project/Mlops/myenv/lib/python3.12/site-packages/airflow/utils/operator_helpers.py", line 252, in run
    return self.func(*args, **kwargs)
           ^^^^^^^^^^^^^^^^^^^^^^^^^^
  File "/home/hamza/Documents/project/Mlops/airflow/dags/news_scrapper.py", line 128, in store_in_data_lake
    if not minio_client.bucket_exists(bucket):
           ^^^^^^^^^^^^^^^^^^^^^^^^^^^^^^^^^^
  File "/home/hamza/Documents/project/Mlops/myenv/lib/python3.12/site-packages/minio/api.py", line 697, in bucket_exists
    self._execute("HEAD", bucket_name)
  File "/home/hamza/Documents/project/Mlops/myenv/lib/python3.12/site-packages/minio/api.py", line 438, in _execute
    region = self._get_region(bucket_name)
             ^^^^^^^^^^^^^^^^^^^^^^^^^^^^^
  File "/home/hamza/Documents/project/Mlops/myenv/lib/python3.12/site-packages/minio/api.py", line 495, in _get_region
    response = self._url_open(
               ^^^^^^^^^^^^^^^
  File "/home/hamza/Documents/project/Mlops/myenv/lib/python3.12/site-packages/minio/api.py", line 424, in _url_open
    raise response_error
minio.error.S3Error: S3 operation failed; code: InvalidAccessKeyId, message: The Access Key Id you provided does not exist in our records., resource: /retail-news, request_id: 1832D44069D7059F, host_id: dd9025bab4ad464b049177c95eb6ebf374d3b3fd1af9251148b658df7ac2e3e8, bucket_name: retail-news
[2025-04-03T14:09:38.884+0000] {logging_mixin.py:190} INFO - Task instance in failure state
[2025-04-03T14:09:38.885+0000] {logging_mixin.py:190} INFO - Task start:2025-04-03 14:09:38.605697+00:00 end:2025-04-03 14:09:38.883846+00:00 duration:0.278149
[2025-04-03T14:09:38.885+0000] {logging_mixin.py:190} INFO - Task:<Task(PythonOperator): store_in_data_lake> dag:<DAG: news_api_collection> dagrun:<DagRun news_api_collection @ 2025-04-03 13:59:54.182119+00:00: manual__2025-04-03T13:59:54.182119+00:00, state:running, queued_at: 2025-04-03 13:59:54.253553+00:00. externally triggered: True>
[2025-04-03T14:09:38.886+0000] {logging_mixin.py:190} INFO - Failure caused by S3 operation failed; code: InvalidAccessKeyId, message: The Access Key Id you provided does not exist in our records., resource: /retail-news, request_id: 1832D44069D7059F, host_id: dd9025bab4ad464b049177c95eb6ebf374d3b3fd1af9251148b658df7ac2e3e8, bucket_name: retail-news
[2025-04-03T14:09:38.886+0000] {taskinstance.py:1226} INFO - Marking task as UP_FOR_RETRY. dag_id=news_api_collection, task_id=store_in_data_lake, run_id=manual__2025-04-03T13:59:54.182119+00:00, execution_date=20250403T135954, start_date=20250403T140938, end_date=20250403T140938
[2025-04-03T14:09:38.924+0000] {taskinstance.py:341} INFO - ::group::Post task execution logs
[2025-04-03T14:09:38.925+0000] {standard_task_runner.py:124} ERROR - Failed to execute job 12 for task store_in_data_lake (S3 operation failed; code: InvalidAccessKeyId, message: The Access Key Id you provided does not exist in our records., resource: /retail-news, request_id: 1832D44069D7059F, host_id: dd9025bab4ad464b049177c95eb6ebf374d3b3fd1af9251148b658df7ac2e3e8, bucket_name: retail-news; 117762)
Traceback (most recent call last):
  File "/home/hamza/Documents/project/Mlops/myenv/lib/python3.12/site-packages/airflow/task/task_runner/standard_task_runner.py", line 117, in _start_by_fork
    ret = args.func(args, dag=self.dag)
          ^^^^^^^^^^^^^^^^^^^^^^^^^^^^^
  File "/home/hamza/Documents/project/Mlops/myenv/lib/python3.12/site-packages/airflow/cli/cli_config.py", line 49, in command
    return func(*args, **kwargs)
           ^^^^^^^^^^^^^^^^^^^^^
  File "/home/hamza/Documents/project/Mlops/myenv/lib/python3.12/site-packages/airflow/utils/cli.py", line 116, in wrapper
    return f(*args, **kwargs)
           ^^^^^^^^^^^^^^^^^^
  File "/home/hamza/Documents/project/Mlops/myenv/lib/python3.12/site-packages/airflow/cli/commands/task_command.py", line 483, in task_run
    task_return_code = _run_task_by_selected_method(args, _dag, ti)
                       ^^^^^^^^^^^^^^^^^^^^^^^^^^^^^^^^^^^^^^^^^^^^
  File "/home/hamza/Documents/project/Mlops/myenv/lib/python3.12/site-packages/airflow/cli/commands/task_command.py", line 256, in _run_task_by_selected_method
    return _run_raw_task(args, ti)
           ^^^^^^^^^^^^^^^^^^^^^^^
  File "/home/hamza/Documents/project/Mlops/myenv/lib/python3.12/site-packages/airflow/cli/commands/task_command.py", line 341, in _run_raw_task
    return ti._run_raw_task(
           ^^^^^^^^^^^^^^^^^
  File "/home/hamza/Documents/project/Mlops/myenv/lib/python3.12/site-packages/airflow/utils/session.py", line 97, in wrapper
    return func(*args, session=session, **kwargs)
           ^^^^^^^^^^^^^^^^^^^^^^^^^^^^^^^^^^^^^^
  File "/home/hamza/Documents/project/Mlops/myenv/lib/python3.12/site-packages/airflow/models/taskinstance.py", line 3006, in _run_raw_task
    return _run_raw_task(
           ^^^^^^^^^^^^^^
  File "/home/hamza/Documents/project/Mlops/myenv/lib/python3.12/site-packages/airflow/models/taskinstance.py", line 274, in _run_raw_task
    TaskInstance._execute_task_with_callbacks(
  File "/home/hamza/Documents/project/Mlops/myenv/lib/python3.12/site-packages/airflow/models/taskinstance.py", line 3161, in _execute_task_with_callbacks
    result = self._execute_task(context, task_orig)
             ^^^^^^^^^^^^^^^^^^^^^^^^^^^^^^^^^^^^^^
  File "/home/hamza/Documents/project/Mlops/myenv/lib/python3.12/site-packages/airflow/models/taskinstance.py", line 3185, in _execute_task
    return _execute_task(self, context, task_orig)
           ^^^^^^^^^^^^^^^^^^^^^^^^^^^^^^^^^^^^^^^
  File "/home/hamza/Documents/project/Mlops/myenv/lib/python3.12/site-packages/airflow/models/taskinstance.py", line 768, in _execute_task
    result = _execute_callable(context=context, **execute_callable_kwargs)
             ^^^^^^^^^^^^^^^^^^^^^^^^^^^^^^^^^^^^^^^^^^^^^^^^^^^^^^^^^^^^^
  File "/home/hamza/Documents/project/Mlops/myenv/lib/python3.12/site-packages/airflow/models/taskinstance.py", line 734, in _execute_callable
    return ExecutionCallableRunner(
           ^^^^^^^^^^^^^^^^^^^^^^^^
  File "/home/hamza/Documents/project/Mlops/myenv/lib/python3.12/site-packages/airflow/utils/operator_helpers.py", line 252, in run
    return self.func(*args, **kwargs)
           ^^^^^^^^^^^^^^^^^^^^^^^^^^
  File "/home/hamza/Documents/project/Mlops/myenv/lib/python3.12/site-packages/airflow/models/baseoperator.py", line 424, in wrapper
    return func(self, *args, **kwargs)
           ^^^^^^^^^^^^^^^^^^^^^^^^^^^
  File "/home/hamza/Documents/project/Mlops/myenv/lib/python3.12/site-packages/airflow/operators/python.py", line 238, in execute
    return_value = self.execute_callable()
                   ^^^^^^^^^^^^^^^^^^^^^^^
  File "/home/hamza/Documents/project/Mlops/myenv/lib/python3.12/site-packages/airflow/operators/python.py", line 256, in execute_callable
    return runner.run(*self.op_args, **self.op_kwargs)
           ^^^^^^^^^^^^^^^^^^^^^^^^^^^^^^^^^^^^^^^^^^^
  File "/home/hamza/Documents/project/Mlops/myenv/lib/python3.12/site-packages/airflow/utils/operator_helpers.py", line 252, in run
    return self.func(*args, **kwargs)
           ^^^^^^^^^^^^^^^^^^^^^^^^^^
  File "/home/hamza/Documents/project/Mlops/airflow/dags/news_scrapper.py", line 128, in store_in_data_lake
    if not minio_client.bucket_exists(bucket):
           ^^^^^^^^^^^^^^^^^^^^^^^^^^^^^^^^^^
  File "/home/hamza/Documents/project/Mlops/myenv/lib/python3.12/site-packages/minio/api.py", line 697, in bucket_exists
    self._execute("HEAD", bucket_name)
  File "/home/hamza/Documents/project/Mlops/myenv/lib/python3.12/site-packages/minio/api.py", line 438, in _execute
    region = self._get_region(bucket_name)
             ^^^^^^^^^^^^^^^^^^^^^^^^^^^^^
  File "/home/hamza/Documents/project/Mlops/myenv/lib/python3.12/site-packages/minio/api.py", line 495, in _get_region
    response = self._url_open(
               ^^^^^^^^^^^^^^^
  File "/home/hamza/Documents/project/Mlops/myenv/lib/python3.12/site-packages/minio/api.py", line 424, in _url_open
    raise response_error
minio.error.S3Error: S3 operation failed; code: InvalidAccessKeyId, message: The Access Key Id you provided does not exist in our records., resource: /retail-news, request_id: 1832D44069D7059F, host_id: dd9025bab4ad464b049177c95eb6ebf374d3b3fd1af9251148b658df7ac2e3e8, bucket_name: retail-news
[2025-04-03T14:09:38.962+0000] {local_task_job_runner.py:266} INFO - Task exited with return code 1
[2025-04-03T14:09:38.987+0000] {taskinstance.py:3901} INFO - 0 downstream tasks scheduled from follow-on schedule check
[2025-04-03T14:09:38.989+0000] {local_task_job_runner.py:245} INFO - ::endgroup::
